const myFunc = () => {
try{
throw ("error found")
}
catch (error){
    console.log("error")
}

}

